Workbook

Sheet Balance des comptes
A2: MCI CARE MADAGASCAR | I2: Balance des comptes | O2: Période du | P2: 46023
O3: au | P3: 46387
I4: Complète | O4: Tenue de compte : MGA
A6: © Sage - Sage 100cloud Comptabilité Standard 6.01 | I6: Date de tirage | K6: 46295 | M6: à | N6: 0.49244213 | P6: Page : | R6: 1
A8: Numéro de compte | J8: Mouvements | P8: Soldes
E9: Intitulé des comptes
J10: Débit | L10: Crédit | O10: Débit | Q10: Crédit
A13: 101000 | C13: Capital social | M13: 1000000 | R13: 1000000
A14: 110000 | C14: Report à nouveau (créditeur) | M14: 3.6357538e+08 | R14: 3.6357538e+08
A15: 120000 | C15: Résultat exercice (bénéfice) | J15: 2.0190225e+08 | M15: 1.4335208e+09 | R15: 1.2316186e+09
A16: 129000 | C16: Résultat exercice (perte) | J16: 27022531 | O16: 27022531
A17: 204000 | C17: Logiciels informatiques et assimilé | J17: 63305140 | O17: 63305140
A18: 212000 | C18: Mobilier de bureau | J18: 11611131 | O18: 11611131
A19: 215000 | C19: Installation technique | J19: 230000 | O19: 230000
A20: 216000 | C20: Matériel Outillage | J20: 290000 | O20: 290000
A21: 218200 | C21: Matériel informatique | J21: 2.5723672e+08 | O21: 2.5723672e+08
A22: 238000 | C22: Immobilisation incorporelle en cour | J22: 12536740 | O22: 12536740
A23: 275000 | C23: Dépots et cautionnements verés-CHU | J23: 800000 | O23: 800000
A24: 280400 | C24: Amortissement logiciel | M24: 62906140 | R24: 62906140
A25: 281200 | C25: Amortissement mobilier de bureau | M25: 8261092.3 | R25: 8261092.3
A26: 281500 | C26: Amortissement installation techniqu | M26: 230000 | R26: 230000
A27: 281600 | C27: Amortissement matériel et outillage | M27: 290000 | R27: 290000
A28: 281820 | C28: Amortissement matériel informatique | M28: 1.7915165e+08 | R28: 1.7915165e+08
A29: 401000 | C29: Prestataire | J29: 7.7207628e+09 | M29: 7.7187505e+09 | O29: 2012346
A30: 401100 | C30: Fournisseur MCI Care | J30: 4.7984224e+08 | M30: 4.9926144e+08 | R30: 19419197
A31: 408000 | C31: facture non parvenue | J31: 22987486 | M31: 22987486
A32: 409300 | C32: avances fournisseur local | J32: 72000 | M32: 72000
A33: 411100 | C33: SANLAM | J33: 2.7186415e+08 | M33: 2.7186415e+08 | R33: 0.019999981
A34: 411102 | C34: EXSANLAMALLIANZ | J34: 38525178 | M34: 38525178
A35: 411103 | C35: SANLAMALLIANZ | J35: 7.2894338e+08 | M35: 6.2136827e+08 | O35: 1.0757511e+08
A36: 411110 | C36: HOLCIM/CEMENTIS | J36: 68830658 | M36: 61469636 | O36: 7361022
A37: 411121 | C37: DHL EXPRESS | J37: 8184360.2 | M37: 8184360.2
A38: 411122 | C38: DHL FORWARDING | J38: 10738898 | M38: 8463454.9 | O38: 2275443.1
A39: 411123 | C39: MGS | J39: 943987.2 | O39: 943987.2
A40: 411124 | C40: FSS | J40: 8415340.3 | M40: 4661536.5 | O40: 3753803.8
A41: 411130 | C41: PAMF | J41: 77571040 | M41: 77571040
A42: 411140 | C42: TELMA | J42: 45700000 | M42: 45700000
A43: 411145 | C43: TELMA MONEY | J43: 15988672 | M43: 15988672
A44: 411150 | C44: JOVENA | J44: 15886567 | M44: 15886567
A45: 411160 | C45: ERNST & YOUNG | J45: 10284505 | M45: 10284505
...

Sheet 2026
A1: HOLCIM | C1: DEBIT | D1: CREDIT | E1: SOLDE
B2: 467110 | C2: =IFERROR(INDEX('Balance des comptes'!$O:$O,MATCH('2026'!B2,'Balance des comptes'!$A:$A,0)),0) -> 0 | D2: =IFERROR(INDEX('Balance des comptes'!$R:$R,MATCH('2026'!B2,'Balance des comptes'!$A:$A,0)),0) -> 32571587 | E2: =+C2-D2 -> -32571587
B3: 460110 | C3: =IFERROR(INDEX('Balance des comptes'!$O:$O,MATCH('2026'!B3,'Balance des comptes'!$A:$A,0)),0) -> 30278601 | D3: =IFERROR(INDEX('Balance des comptes'!$R:$R,MATCH('2026'!B3,'Balance des comptes'!$A:$A,0)),0) -> 0 | E3: =+C3-D3 -> 30278601
B4: 461110 | C4: =IFERROR(INDEX('Balance des comptes'!$O:$O,MATCH('2026'!B4,'Balance des comptes'!$A:$A,0)),0) -> 0 | D4: =IFERROR(INDEX('Balance des comptes'!$R:$R,MATCH('2026'!B4,'Balance des comptes'!$A:$A,0)),0) -> 0 | E4: =+C4-D4 -> 0
B5: 462110 | C5: =IFERROR(INDEX('Balance des comptes'!$O:$O,MATCH('2026'!B5,'Balance des comptes'!$A:$A,0)),0) -> 0 | D5: =IFERROR(INDEX('Balance des comptes'!$R:$R,MATCH('2026'!B5,'Balance des comptes'!$A:$A,0)),0) -> 170100 | E5: =+C5-D5 -> -170100
B6: Solde Appel de fonds | C6: =SUM(C2:C5) -> 30278601 | D6: =SUM(D2:D5) -> 32741687 | E6: =SUM(E2:E5) -> -2463085.9
B7: 512110 | C7: =IFERROR(INDEX('Balance des comptes'!$O:$O,MATCH('2026'!B7,'Balance des comptes'!$A:$A,0)),0) -> 1489728.7 | D7: =IFERROR(INDEX('Balance des comptes'!$R:$R,MATCH('2026'!B7,'Balance des comptes'!$A:$A,0)),0) -> 0 | E7: =+C7-D7 -> 1489728.7
B8: Solde Trésorerie | C8: =SUM(C7:C7) -> 1489728.7 | D8: =SUM(D7:D7) -> 0 | E8: =SUM(E7:E7) -> 1489728.7
B10: Vérification | E10: =+E6+E8 -> -973357.22
A12: DHL INTERNATIONAL | C12: DEBIT | D12: CREDIT | E12: SOLDE
B13: 467120 | C13: =IFERROR(INDEX('Balance des comptes'!$O:$O,MATCH('2026'!B13,'Balance des comptes'!$A:$A,0)),0) -> 0 | D13: =IFERROR(INDEX('Balance des comptes'!$R:$R,MATCH('2026'!B13,'Balance des comptes'!$A:$A,0)),0) -> 1.4047267e+08 | E13: =+C13-D13 -> -1.4047267e+08
B14: 460120 | C14: =IFERROR(INDEX('Balance des comptes'!$O:$O,MATCH('2026'!B14,'Balance des comptes'!$A:$A,0)),0) -> 0 | D14: =IFERROR(INDEX('Balance des comptes'!$R:$R,MATCH('2026'!B14,'Balance des comptes'!$A:$A,0)),0) -> 0 | E14: =+C14-D14 -> 0
B15: 461120 | C15: =IFERROR(INDEX('Balance des comptes'!$O:$O,MATCH('2026'!B15,'Balance des comptes'!$A:$A,0)),0) -> 0 | D15: =IFERROR(INDEX('Balance des comptes'!$R:$R,MATCH('2026'!B15,'Balance des comptes'!$A:$A,0)),0) -> 0 | E15: =+C15-D15 -> 0
B16: 462120 | C16: =IFERROR(INDEX('Balance des comptes'!$O:$O,MATCH('2026'!B16,'Balance des comptes'!$A:$A,0)),0) -> 0 | D16: =IFERROR(INDEX('Balance des comptes'!$R:$R,MATCH('2026'!B16,'Balance des comptes'!$A:$A,0)),0) -> 0 | E16: =+C16-D16 -> 0
B17: Solde Appel de fonds | C17: =SUM(C13:C16) -> 0 | D17: =SUM(D13:D16) -> 1.4047267e+08 | E17: =SUM(E13:E16) -> -1.4047267e+08
B18: 512120 | C18: =IFERROR(INDEX('Balance des comptes'!$O:$O,MATCH('2026'!B18,'Balance des comptes'!$A:$A,0)),0) -> 0 | D18: =IFERROR(INDEX('Balance des comptes'!$R:$R,MATCH('2026'!B18,'Balance des comptes'!$A:$A,0)),0) -> 69969.22 | E18: =+C18-D18 -> -69969.22 | G18: Solde Appel de fonds | H18: =+E17+E28 -> 69969.02
B19: Solde Trésorerie | C19: =SUM(C18:C18) -> 0 | D19: =SUM(D18:D18) -> 69969.22 | E19: =SUM(E18:E18)-E15 -> -69969.22 | G19: Solde Trésorerie | H19: =+E19 -> -69969.22
G20: Vérification | H20: =+H18+H19 -> -0.20000002
B21: Vérification | E21: =+E17+E19 -> -1.4054264e+08
A23: DHL EXPRESS | C23: DEBIT | D23: CREDIT | E23: SOLDE
B24: 467121 | C24: =IFERROR(INDEX('Balance des comptes'!$O:$O,MATCH('2026'!B24,'Balance des comptes'!$A:$A,0)),0) -> 1.4430838e+08 | D24: =IFERROR(INDEX('Balance des comptes'!$R:$R,MATCH('2026'!B24,'Balance des comptes'!$A:$A,0)),0) -> 0 | E24: =+C24-D24 -> 1.4430838e+08
B25: 460121 | C25: =IFERROR(INDEX('Balance des comptes'!$O:$O,MATCH('2026'!B25,'Balance des comptes'!$A:$A,0)),0) -> 0 | D25: =IFERROR(INDEX('Balance des comptes'!$R:$R,MATCH('2026'!B25,'Balance des comptes'!$A:$A,0)),0) -> 0 | E25: =+C25-D25 -> 0
B26: 461121 | C26: =IFERROR(INDEX('Balance des comptes'!$O:$O,MATCH('2026'!B26,'Balance des comptes'!$A:$A,0)),0) -> 0 | D26: =IFERROR(INDEX('Balance des comptes'!$R:$R,MATCH('2026'!B26,'Balance des comptes'!$A:$A,0)),0) -> 0 | E26: =+C26-D26 -> 0
B27: 462121 | C27: =IFERROR(INDEX('Balance des comptes'!$O:$O,MATCH('2026'!B27,'Balance des comptes'!$A:$A,0)),0) -> 0 | D27: =IFERROR(INDEX('Balance des comptes'!$R:$R,MATCH('2026'!B27,'Balance des comptes'!$A:$A,0)),0) -> 3765734 | E27: =+C27-D27 -> -3765734
B28: Solde Appel de fonds | C28: =SUM(C24:C27) -> 1.4430838e+08 | D28: =SUM(D24:D27) -> 3765734 | E28: =SUM(E24:E27) -> 1.4054264e+08
A31: MGS | C31: DEBIT | D31: CREDIT | E31: SOLDE
B32: 467123 | C32: =IFERROR(INDEX('Balance des comptes'!$O:$O,MATCH('2026'!B32,'Balance des comptes'!$A:$A,0)),0) -> 0 | D32: =IFERROR(INDEX('Balance des comptes'!$R:$R,MATCH('2026'!B32,'Balance des comptes'!$A:$A,0)),0) -> 5416187.9 | E32: =+C32-D32 -> -5416187.9
B33: 460123 | C33: =IFERROR(INDEX('Balance des comptes'!$O:$O,MATCH('2026'!B33,'Balance des comptes'!$A:$A,0)),0) -> 0 | D33: =IFERROR(INDEX('Balance des comptes'!$R:$R,MATCH('2026'!B33,'Balance des comptes'!$A:$A,0)),0) -> 0 | E33: =+C33-D33 -> 0 | G33: Solde Appel de fonds | H33: =+E36+E43 -> -8624968.8
B34: 461123 | C34: =IFERROR(INDEX('Balance des comptes'!$O:$O,MATCH('2026'!B34,'Balance des comptes'!$A:$A,0)),0) -> 0 | D34: =IFERROR(INDEX('Balance des comptes'!$R:$R,MATCH('2026'!B34,'Balance des comptes'!$A:$A,0)),0) -> 0 | E34: =+C34-D34 -> 0 | G34: Solde Trésorerie | H34: =+E45 -> 8795039.8
B35: 462123 | C35: =IFERROR(INDEX('Balance des comptes'!$O:$O,MATCH('2026'!B35,'Balance des comptes'!$A:$A,0)),0) -> 0 | D35: =IFERROR(INDEX('Balance des comptes'!$R:$R,MATCH('2026'!B35,'Balance des comptes'!$A:$A,0)),0) -> 201300 | E35: =+C35-D35 -> -201300 | G35: Vérification | H35: =+H33+H34 -> 170071
B36: Solde Appel de fonds | C36: =SUM(C32:C35) -> 0 | D36: =SUM(D32:D35) -> 5617487.9 | E36: =SUM(E32:E35) -> -5617487.9
A38: FSS | C38: DEBIT | D38: CREDIT | E38: SOLDE
B39: 467124 | C39: =IFERROR(INDEX('Balance des comptes'!$O:$O,MATCH('2026'!B39,'Balance des comptes'!$A:$A,0)),0) -> 0 | D39: =IFERROR(INDEX('Balance des comptes'!$R:$R,MATCH('2026'!B39,'Balance des comptes'!$A:$A,0)),0) -> 20288474 | E39: =+C39-D39 -> -20288474
B40: 460124 | C40: =IFERROR(INDEX('Balance des comptes'!$O:$O,MATCH('2026'!B40,'Balance des comptes'!$A:$A,0)),0) -> 17280994 | D40: =IFERROR(INDEX('Balance des comptes'!$R:$R,MATCH('2026'!B40,'Balance des comptes'!$A:$A,0)),0) -> 0 | E40: =+C40-D40 -> 17280994
B41: 461124 | C41: =IFERROR(INDEX('Balance des comptes'!$O:$O,MATCH('2026'!B41,'Balance des comptes'!$A:$A,0)),0) -> 0 | D41: =IFERROR(INDEX('Balance des comptes'!$R:$R,MATCH('2026'!B41,'Balance des comptes'!$A:$A,0)),0) -> 0 | E41: =+C41-D41 -> 0
B42: 462124 | C42: =IFERROR(INDEX('Balance des comptes'!$O:$O,MATCH('2026'!B42,'Balance des comptes'!$A:$A,0)),0) -> 0 | D42: =IFERROR(INDEX('Balance des comptes'!$R:$R,MATCH('2026'!B42,'Balance des comptes'!$A:$A,0)),0) -> 0 | E42: =+C42-D42 -> 0
B43: Solde Appel de fonds | C43: =SUM(C39:C42) -> 17280994 | D43: =SUM(D39:D42) -> 20288474 | E43: =SUM(E39:E42) -> -3007480.9
B44: 512124 | C44: =IFERROR(INDEX('Balance des comptes'!$O:$O,MATCH('2026'!B44,'Balance des comptes'!$A:$A,0)),0) -> 8795039.8 | D44: =IFERROR(INDEX('Balance des comptes'!$R:$R,MATCH('2026'!B44,'Balance des comptes'!$A:$A,0)),0) -> 0 | E44: =+C44-D44 -> 8795039.8
B45: Solde Trésorerie | C45: =SUM(C44:C44) -> 8795039.8 | D45: =SUM(D44:D44) -> 0 | E45: =SUM(E44:E44) -> 8795039.8
B47: Vérification | E47: =+E43+E45+E36 -> 170071
...

Sheet Feuil1
A1: P | B1: Code journal | C1: Date | D1: N° pièce | E1: Référence | F1: N° facture | G1: N° compte tiers | H1: Libellé écriture | I1: Date échéance | J1: Lettrage montant | K1: Pointage | L1: Débit | M1: Crédit
A2: 0 | B2: RAN | C2: 45658 | D2: ="36" -> 36 | G2: CLTDHLEXPRESS | H2: A.N. au 010123 | M2: 80866901
A3: 0 | B3: RAN | C3: 45658 | D3: ="36" -> 36 | G3: FONDHLEXPRESS | H3: A.N. au 010123 | M3: 1.8592069e+08
A4: 0 | B4: OD | C4: 45666 | D4: ="80" -> 80 | E4: 45666 | G4: FONDHLEXPRESS | H4: COMPENSATION FOND-HONORAIRE-REG-2024-11-FA-DHL EXPRESS | L4: 3103598.9
A5: 0 | B5: TIERS | C5: 45658 | D5: ="83" -> 83 | E5: 45649 | F5: 24325/357091 | G5: FONDHLEXPRESS | H5: DHL EXPRESS DECEMBRE 2024- PHARMACIE PRINCIPALE- REG 24325/357091 | L5: 644160
A6: 0 | B6: TIERS | C6: 45658 | D6: ="83" -> 83 | E6: 45655 | F6: LOT24899/363018 | G6: FONDHLEXPRESS | H6: DHL EXPRESS DECEMBRE 2024- PHARMACIE PRINCIPALE- REG LOT24899/363018 | L6: 383600
A7: 0 | B7: TIERS | C7: 45658 | D7: ="83" -> 83 | E7: 45656 | F7: LOT24548/358721 | G7: FONDHLEXPRESS | H7: DHL EXPRESS DECEMBRE 2024- PHARMACIE PRINCIPALE- REG LOT24548/358721 | L7: 598720
A8: 0 | B8: TIERS | C8: 45658 | D8: ="330" -> 330 | E8: 45657 | F8: ="21739" -> 21739 | G8: FONDHLEXPRESS | H8: DHL EXPRESS DECEMBRE 2024- RAZAFIMANANTSOA TIANA NIRINA- RMBT 21739 | L8: 110000
A9: 0 | B9: TIERS | C9: 45658 | D9: ="330" -> 330 | E9: 45657 | F9: ="21740" -> 21740 | G9: FONDHLEXPRESS | H9: DHL EXPRESS DECEMBRE 2024- RANAIVO IONIMALALA- RMBT 21740 | L9: 798400
A10: 0 | B10: TIERS | C10: 45658 | D10: ="432" -> 432 | E10: 45629 | F10: ="344896" -> 344896 | G10: FONDHLEXPRESS | H10: DHL EXPRESS DECEMBRE 2024- LUXOPTICA- REG 344896 | L10: 547200
A11: 0 | B11: TIERS | C11: 45658 | D11: ="432" -> 432 | E11: 45629 | F11: 24/3715 | G11: FONDHLEXPRESS | H11: DHL EXPRESS DECEMBRE 2024- CLINIQUE NOA- REG 24/3715 | L11: 84000
A12: 0 | B12: TIERS | C12: 45658 | D12: ="432" -> 432 | E12: 45629 | F12: ="251256" -> 251256 | G12: FONDHLEXPRESS | H12: DHL EXPRESS DECEMBRE 2024- PHARMACIE DU ROI- REG 251256 | L12: 76320
A13: 0 | B13: TIERS | C13: 45658 | D13: ="432" -> 432 | E13: 45639 | F13: FGC/000234/2024 | G13: FONDHLEXPRESS | H13: DHL EXPRESS DECEMBRE 2024- PHARMACIE D'ANKADINDRATOMBO- REG FGC/00023 | L13: 156960
A14: 0 | B14: TIERS | C14: 45658 | D14: ="432" -> 432 | E14: 45639 | F14: 1906/24Y | G14: FONDHLEXPRESS | H14: DHL EXPRESS DECEMBRE 2024- PHARMACIE TSARASANDRY- REG 1906/24Y | L14: 30240
A15: 0 | B15: TIERS | C15: 45658 | D15: ="432" -> 432 | E15: 45639 | F15: 2024/179 | G15: FONDHLEXPRESS | H15: DHL EXPRESS DECEMBRE 2024- SP VISION- REG 2024/179 | L15: 140000
A16: 0 | B16: TIERS | C16: 45658 | D16: ="432" -> 432 | E16: 45639 | F16: 15761/278774 | G16: FONDHLEXPRESS | H16: DHL EXPRESS DECEMBRE 2024- PHARMACIE MANDROSOA- REG 15761/278774 | L16: 136640
A17: 0 | B17: TIERS | C17: 45658 | D17: ="432" -> 432 | E17: 45642 | F17: ="202404005" -> 202404005 | G17: FONDHLEXPRESS | H17: DHL EXPRESS DECEMBRE 2024- CENTRE MEDICAL AMBATOMENA- REG 202404005 | L17: 16000
A18: 0 | B18: TIERS | C18: 45658 | D18: ="432" -> 432 | E18: 45642 | F18: FAC 11052024 | G18: FONDHLEXPRESS | H18: DHL EXPRESS DECEMBRE 2024- DR MIRAFINARITRA RAFIDIARIMANANA- REG FAC | L18: 672000
A19: 0 | B19: TIERS | C19: 45658 | D19: ="432" -> 432 | E19: 45642 | F19: 1712/ALH/2024 | G19: FONDHLEXPRESS | H19: DHL EXPRESS DECEMBRE 2024- POLYCLINIQUE ILAFY- REG 1712/ALH/2024 | L19: 15200
A20: 0 | B20: TIERS | C20: 45658 | D20: ="432" -> 432 | E20: 45642 | F20: ="0124" -> 0124 | G20: FONDHLEXPRESS | H20: DHL EXPRESS DECEMBRE 2024- CENTRE MEDICAL COLISEUM- REG 0124 | L20: 148800
A21: 0 | B21: TIERS | C21: 45658 | D21: ="432" -> 432 | E21: 45649 | F21: ="41130" -> 41130 | G21: FONDHLEXPRESS | H21: DHL EXPRESS DECEMBRE 2024- CABINET NOOR (OPHTALMO)- REG 41130 | L21: 28000
A22: 0 | B22: TIERS | C22: 45658 | D22: ="432" -> 432 | E22: 45649 | F22: FAC 21052024 | G22: FONDHLEXPRESS | H22: DHL EXPRESS DECEMBRE 2024- EYE CARE (OPHTALMO)- REG FAC 21052024 | L22: 28000
A23: 0 | B23: TIERS | C23: 45658 | D23: ="432" -> 432 | E23: 45649 | F23: 1501/24/Y | G23: FONDHLEXPRESS | H23: DHL EXPRESS DECEMBRE 2024- PHARMACIE TSARASANDRY- REG 1501/24/Y | L23: 162160
A24: 0 | B24: TIERS | C24: 45658 | D24: ="432" -> 432 | E24: 45649 | F24: DC 060824 | G24: FONDHLEXPRESS | H24: DHL EXPRESS DECEMBRE 2024- PHARMACIE AMBOHIDRATRIMO- REG DC 060824 | L24: 19360
A25: 0 | B25: TIERS | C25: 45658 | D25: ="432" -> 432 | E25: 45649 | F25: ="343404" -> 343404 | G25: FONDHLEXPRESS | H25: DHL EXPRESS DECEMBRE 2024- LUXOPTICA- REG 343404 | L25: 1124224
A26: 0 | B26: TIERS | C26: 45658 | D26: ="432" -> 432 | E26: 45649 | F26: 24E02583 | G26: FONDHLEXPRESS | H26: DHL EXPRESS DECEMBRE 2024- HEALTH LABO- REG 24E02583 | L26: 227840
A27: 0 | B27: TIERS | C27: 45658 | D27: ="432" -> 432 | E27: 45649 | F27: 01/DHL 2024 | G27: FONDHLEXPRESS | H27: DHL EXPRESS DECEMBRE 2024- ESPACE MEDICAL ANTSIRABE- REG 01/DHL 2024 | L27: 165200
A28: 0 | B28: TIERS | C28: 45658 | D28: ="432" -> 432 | E28: 45649 | F28: 111490/PH/AV/2024 | G28: FONDHLEXPRESS | H28: DHL EXPRESS DECEMBRE 2024- PHARMACIE D'AVARADRANO- REG 111490/PH/AV/2 | L28: 1094880
A29: 0 | B29: TIERS | C29: 45658 | D29: ="432" -> 432 | E29: 45649 | F29: 07-2023/CSL | G29: FONDHLEXPRESS | H29: DHL EXPRESS DECEMBRE 2024- IMAGERIE DE LA CLINIQUE SAINT LAURENT - RE | L29: 48000
A30: 0 | B30: TIERS | C30: 45658 | D30: ="432" -> 432 | E30: 45649 | F30: VP-1051592 | G30: FONDHLEXPRESS | H30: DHL EXPRESS DECEMBRE 2024- PHARMACIE GRACE- REG VP-1051592 | L30: 455520
A31: 0 | B31: TIERS | C31: 45658 | D31: ="432" -> 432 | E31: 45649 | F31: 0924/003 | G31: FONDHLEXPRESS | H31: DHL EXPRESS DECEMBRE 2024- CENTRE MEDICAL COLISEUM- REG 0924/003 | L31: 24000
A32: 0 | B32: TIERS | C32: 45658 | D32: ="432" -> 432 | E32: 45649 | F32: FAC 26102024 | G32: FONDHLEXPRESS | H32: DHL EXPRESS DECEMBRE 2024- ZOOM OPTIQUE (OPHTALMO)- REG FAC 26102024 | L32: 56000
A33: 0 | B33: TIERS | C33: 45658 | D33: ="432" -> 432 | E33: 45649 | F33: ="17517" -> 17517 | G33: FONDHLEXPRESS | H33: DHL EXPRESS DECEMBRE 2024- ZOOM OPTIQUE- REG 17517 | L33: 609600
A34: 0 | B34: TIERS | C34: 45658 | D34: ="432" -> 432 | E34: 45649 | F34: IS 20 241 213 | G34: FONDHLEXPRESS | H34: DHL EXPRESS DECEMBRE 2024- CLINIQUE ET MATERNITE SAINT FRANCOIS D'ASS | L34: 32000
A35: 0 | B35: TIERS | C35: 45658 | D35: ="432" -> 432 | E35: 45649 | F35: FAC 02102024 | G35: FONDHLEXPRESS | H35: DHL EXPRESS DECEMBRE 2024- SAINT JOSEPH MEDICAL SERVICES- REG FAC 021 | L35: 12800
A36: 0 | B36: TIERS | C36: 45658 | D36: ="432" -> 432 | E36: 45649 | F36: 15838/279257 | G36: FONDHLEXPRESS | H36: DHL EXPRESS DECEMBRE 2024- PHARMACIE MANDROSOA- REG 15838/279257 | L36: 29520
A37: 0 | B37: TIERS | C37: 45658 | D37: ="432" -> 432 | E37: 45649 | F37: 24/64067 | G37: FONDHLEXPRESS | H37: DHL EXPRESS DECEMBRE 2024- CLINIQUE NOA- REG 24/64067 | L37: 28000
A38: 0 | B38: TIERS | C38: 45658 | D38: ="432" -> 432 | E38: 45652 | F38: FAC/126021/2024 | G38: FONDHLEXPRESS | H38: DHL EXPRESS DECEMBRE 2024- PHARMACIE D'ANKADINDRATOMBO- REG FAC/12602 | L38: 156400
A39: 0 | B39: TIERS | C39: 45658 | D39: ="432" -> 432 | E39: 45657 | F39: FAC 12122024 | G39: FONDHLEXPRESS | H39: DHL EXPRESS DECEMBRE 2024- EYE CARE (OPHTALMO)- REG FAC 12122024 | L39: 28000
A40: 0 | B40: TIERS | C40: 45658 | D40: ="432" -> 432 | E40: 45657 | F40: FS 374965 | G40: FONDHLEXPRESS | H40: DHL EXPRESS DECEMBRE 2024- MARIE STOPES MADAGASCAR TANA- REG FS 37496 | L40: 65600
...

Sheet Feuil2
A1: P | B1: Code journal | C1: Date | D1: N° pièce | E1: Référence | F1: N° facture | G1: N° compte tiers | H1: Libellé écriture | I1: Date échéance | J1: Lettrage montant | K1: Pointage | L1: Débit | M1: Crédit
A2: 0 | B2: RAN | C2: 45658 | D2: ="36" -> 36 | G2: CLTDHLEXPRESS | H2: A.N. au 010123 | M2: 80866901
A3: 0 | B3: RAN | C3: 45658 | D3: ="36" -> 36 | G3: FONDHLEXPRESS | H3: A.N. au 010123 | M3: 1.8592069e+08
A4: 0 | B4: OD | C4: 45666 | D4: ="80" -> 80 | E4: 45666 | G4: FONDHLEXPRESS | H4: COMPENSATION FOND-HONORAIRE-REG-2024-11-FA-DHL EXPRESS | L4: 3103598.9
A5: 0 | B5: TIERS | C5: 45658 | D5: ="83" -> 83 | E5: 45649 | F5: 24325/357091 | G5: FONDHLEXPRESS | H5: DHL EXPRESS DECEMBRE 2024- PHARMACIE PRINCIPALE- REG 24325/357091 | L5: 644160
A6: 0 | B6: TIERS | C6: 45658 | D6: ="83" -> 83 | E6: 45655 | F6: LOT24899/363018 | G6: FONDHLEXPRESS | H6: DHL EXPRESS DECEMBRE 2024- PHARMACIE PRINCIPALE- REG LOT24899/363018 | L6: 383600
A7: 0 | B7: TIERS | C7: 45658 | D7: ="83" -> 83 | E7: 45656 | F7: LOT24548/358721 | G7: FONDHLEXPRESS | H7: DHL EXPRESS DECEMBRE 2024- PHARMACIE PRINCIPALE- REG LOT24548/358721 | L7: 598720
A8: 0 | B8: TIERS | C8: 45658 | D8: ="330" -> 330 | E8: 45657 | F8: ="21739" -> 21739 | G8: FONDHLEXPRESS | H8: DHL EXPRESS DECEMBRE 2024- RAZAFIMANANTSOA TIANA NIRINA- RMBT 21739 | L8: 110000
A9: 0 | B9: TIERS | C9: 45658 | D9: ="330" -> 330 | E9: 45657 | F9: ="21740" -> 21740 | G9: FONDHLEXPRESS | H9: DHL EXPRESS DECEMBRE 2024- RANAIVO IONIMALALA- RMBT 21740 | L9: 798400
A10: 0 | B10: TIERS | C10: 45658 | D10: ="432" -> 432 | E10: 45629 | F10: ="344896" -> 344896 | G10: FONDHLEXPRESS | H10: DHL EXPRESS DECEMBRE 2024- LUXOPTICA- REG 344896 | L10: 547200
A11: 0 | B11: TIERS | C11: 45658 | D11: ="432" -> 432 | E11: 45629 | F11: 24/3715 | G11: FONDHLEXPRESS | H11: DHL EXPRESS DECEMBRE 2024- CLINIQUE NOA- REG 24/3715 | L11: 84000
A12: 0 | B12: TIERS | C12: 45658 | D12: ="432" -> 432 | E12: 45629 | F12: ="251256" -> 251256 | G12: FONDHLEXPRESS | H12: DHL EXPRESS DECEMBRE 2024- PHARMACIE DU ROI- REG 251256 | L12: 76320
A13: 0 | B13: TIERS | C13: 45658 | D13: ="432" -> 432 | E13: 45639 | F13: FGC/000234/2024 | G13: FONDHLEXPRESS | H13: DHL EXPRESS DECEMBRE 2024- PHARMACIE D'ANKADINDRATOMBO- REG FGC/00023 | L13: 156960
A14: 0 | B14: TIERS | C14: 45658 | D14: ="432" -> 432 | E14: 45639 | F14: 1906/24Y | G14: FONDHLEXPRESS | H14: DHL EXPRESS DECEMBRE 2024- PHARMACIE TSARASANDRY- REG 1906/24Y | L14: 30240
A15: 0 | B15: TIERS | C15: 45658 | D15: ="432" -> 432 | E15: 45639 | F15: 2024/179 | G15: FONDHLEXPRESS | H15: DHL EXPRESS DECEMBRE 2024- SP VISION- REG 2024/179 | L15: 140000
A16: 0 | B16: TIERS | C16: 45658 | D16: ="432" -> 432 | E16: 45639 | F16: 15761/278774 | G16: FONDHLEXPRESS | H16: DHL EXPRESS DECEMBRE 2024- PHARMACIE MANDROSOA- REG 15761/278774 | L16: 136640
A17: 0 | B17: TIERS | C17: 45658 | D17: ="432" -> 432 | E17: 45642 | F17: ="202404005" -> 202404005 | G17: FONDHLEXPRESS | H17: DHL EXPRESS DECEMBRE 2024- CENTRE MEDICAL AMBATOMENA- REG 202404005 | L17: 16000
A18: 0 | B18: TIERS | C18: 45658 | D18: ="432" -> 432 | E18: 45642 | F18: FAC 11052024 | G18: FONDHLEXPRESS | H18: DHL EXPRESS DECEMBRE 2024- DR MIRAFINARITRA RAFIDIARIMANANA- REG FAC | L18: 672000
A19: 0 | B19: TIERS | C19: 45658 | D19: ="432" -> 432 | E19: 45642 | F19: 1712/ALH/2024 | G19: FONDHLEXPRESS | H19: DHL EXPRESS DECEMBRE 2024- POLYCLINIQUE ILAFY- REG 1712/ALH/2024 | L19: 15200
A20: 0 | B20: TIERS | C20: 45658 | D20: ="432" -> 432 | E20: 45642 | F20: ="0124" -> 0124 | G20: FONDHLEXPRESS | H20: DHL EXPRESS DECEMBRE 2024- CENTRE MEDICAL COLISEUM- REG 0124 | L20: 148800
A21: 0 | B21: TIERS | C21: 45658 | D21: ="432" -> 432 | E21: 45649 | F21: ="41130" -> 41130 | G21: FONDHLEXPRESS | H21: DHL EXPRESS DECEMBRE 2024- CABINET NOOR (OPHTALMO)- REG 41130 | L21: 28000
A22: 0 | B22: TIERS | C22: 45658 | D22: ="432" -> 432 | E22: 45649 | F22: FAC 21052024 | G22: FONDHLEXPRESS | H22: DHL EXPRESS DECEMBRE 2024- EYE CARE (OPHTALMO)- REG FAC 21052024 | L22: 28000
A23: 0 | B23: TIERS | C23: 45658 | D23: ="432" -> 432 | E23: 45649 | F23: 1501/24/Y | G23: FONDHLEXPRESS | H23: DHL EXPRESS DECEMBRE 2024- PHARMACIE TSARASANDRY- REG 1501/24/Y | L23: 162160
A24: 0 | B24: TIERS | C24: 45658 | D24: ="432" -> 432 | E24: 45649 | F24: DC 060824 | G24: FONDHLEXPRESS | H24: DHL EXPRESS DECEMBRE 2024- PHARMACIE AMBOHIDRATRIMO- REG DC 060824 | L24: 19360
A25: 0 | B25: TIERS | C25: 45658 | D25: ="432" -> 432 | E25: 45649 | F25: ="343404" -> 343404 | G25: FONDHLEXPRESS | H25: DHL EXPRESS DECEMBRE 2024- LUXOPTICA- REG 343404 | L25: 1124224
A26: 0 | B26: TIERS | C26: 45658 | D26: ="432" -> 432 | E26: 45649 | F26: 24E02583 | G26: FONDHLEXPRESS | H26: DHL EXPRESS DECEMBRE 2024- HEALTH LABO- REG 24E02583 | L26: 227840
A27: 0 | B27: TIERS | C27: 45658 | D27: ="432" -> 432 | E27: 45649 | F27: 01/DHL 2024 | G27: FONDHLEXPRESS | H27: DHL EXPRESS DECEMBRE 2024- ESPACE MEDICAL ANTSIRABE- REG 01/DHL 2024 | L27: 165200
A28: 0 | B28: TIERS | C28: 45658 | D28: ="432" -> 432 | E28: 45649 | F28: 111490/PH/AV/2024 | G28: FONDHLEXPRESS | H28: DHL EXPRESS DECEMBRE 2024- PHARMACIE D'AVARADRANO- REG 111490/PH/AV/2 | L28: 1094880
A29: 0 | B29: TIERS | C29: 45658 | D29: ="432" -> 432 | E29: 45649 | F29: 07-2023/CSL | G29: FONDHLEXPRESS | H29: DHL EXPRESS DECEMBRE 2024- IMAGERIE DE LA CLINIQUE SAINT LAURENT - RE | L29: 48000
A30: 0 | B30: TIERS | C30: 45658 | D30: ="432" -> 432 | E30: 45649 | F30: VP-1051592 | G30: FONDHLEXPRESS | H30: DHL EXPRESS DECEMBRE 2024- PHARMACIE GRACE- REG VP-1051592 | L30: 455520
A31: 0 | B31: TIERS | C31: 45658 | D31: ="432" -> 432 | E31: 45649 | F31: 0924/003 | G31: FONDHLEXPRESS | H31: DHL EXPRESS DECEMBRE 2024- CENTRE MEDICAL COLISEUM- REG 0924/003 | L31: 24000
A32: 0 | B32: TIERS | C32: 45658 | D32: ="432" -> 432 | E32: 45649 | F32: FAC 26102024 | G32: FONDHLEXPRESS | H32: DHL EXPRESS DECEMBRE 2024- ZOOM OPTIQUE (OPHTALMO)- REG FAC 26102024 | L32: 56000
A33: 0 | B33: TIERS | C33: 45658 | D33: ="432" -> 432 | E33: 45649 | F33: ="17517" -> 17517 | G33: FONDHLEXPRESS | H33: DHL EXPRESS DECEMBRE 2024- ZOOM OPTIQUE- REG 17517 | L33: 609600
A34: 0 | B34: TIERS | C34: 45658 | D34: ="432" -> 432 | E34: 45649 | F34: IS 20 241 213 | G34: FONDHLEXPRESS | H34: DHL EXPRESS DECEMBRE 2024- CLINIQUE ET MATERNITE SAINT FRANCOIS D'ASS | L34: 32000
A35: 0 | B35: TIERS | C35: 45658 | D35: ="432" -> 432 | E35: 45649 | F35: FAC 02102024 | G35: FONDHLEXPRESS | H35: DHL EXPRESS DECEMBRE 2024- SAINT JOSEPH MEDICAL SERVICES- REG FAC 021 | L35: 12800
A36: 0 | B36: TIERS | C36: 45658 | D36: ="432" -> 432 | E36: 45649 | F36: 15838/279257 | G36: FONDHLEXPRESS | H36: DHL EXPRESS DECEMBRE 2024- PHARMACIE MANDROSOA- REG 15838/279257 | L36: 29520
A37: 0 | B37: TIERS | C37: 45658 | D37: ="432" -> 432 | E37: 45649 | F37: 24/64067 | G37: FONDHLEXPRESS | H37: DHL EXPRESS DECEMBRE 2024- CLINIQUE NOA- REG 24/64067 | L37: 28000
A38: 0 | B38: TIERS | C38: 45658 | D38: ="432" -> 432 | E38: 45652 | F38: FAC/126021/2024 | G38: FONDHLEXPRESS | H38: DHL EXPRESS DECEMBRE 2024- PHARMACIE D'ANKADINDRATOMBO- REG FAC/12602 | L38: 156400
A39: 0 | B39: TIERS | C39: 45658 | D39: ="432" -> 432 | E39: 45657 | F39: FAC 12122024 | G39: FONDHLEXPRESS | H39: DHL EXPRESS DECEMBRE 2024- EYE CARE (OPHTALMO)- REG FAC 12122024 | L39: 28000
A40: 0 | B40: TIERS | C40: 45658 | D40: ="432" -> 432 | E40: 45657 | F40: FS 374965 | G40: FONDHLEXPRESS | H40: DHL EXPRESS DECEMBRE 2024- MARIE STOPES MADAGASCAR TANA- REG FS 37496 | L40: 65600
...
